[52948 | 47792 | ERROR | main.py:164] 2022-04-11 22:57:28,118: ERR : Traceback (most recent call last):
  File "K:/DEVELOPMENT/PYTHON_SAMPLE/DEV_PYTHON_BOT/main.py", line 155, in <module>
    mysql.SelMysq(opt='START')
AttributeError: module 'mysql' has no attribute 'SelMysq'

[52544 | 50340 | ERROR | Errlog.py:32] 2022-04-11 23:14:16,267: ERR : ERR : Traceback (most recent call last):
  File "K:/DEVELOPMENT/PYTHON_SAMPLE/DEV_PYTHON_BOT/main.py", line 129, in <module>
    mysql.SelMysq(opt='START')
AttributeError: module 'mysql' has no attribute 'SelMysq'

[55704 | 47480 | ERROR | Errlog.py:37] 2022-04-12 21:29:36,150: ERR : ERR : NoneType: None

[48172 | 39852 | ERROR | Errlog.py:37] 2022-04-12 21:49:01,769: ERR : ERR : NoneType: None

[16856 | 53216 | ERROR | Errlog.py:37] 2022-04-12 21:49:57,890: ERR : ERR : NoneType: None

[47384 | 56528 | ERROR | Errlog.py:37] 2022-04-12 21:51:01,531: ERR : ERR : NoneType: None

[52500 | 57320 | ERROR | Errlog.py:37] 2022-04-13 22:00:18,923: ERR : ERR : NoneType: None

